Workbook

Sheet Con-Granular
B1: Weapon ID | C1: Ammo Type | D1: Ammo Count | E1: Weapon Toggle | F1: Prop ID | G1: Unk | H1: Scale
A2: Beginner | B2: Rocket Launcher | C2: {=XLOOKUP(TRUE,BYCOL(Data!Q2:AD11, LAMBDA(_xlpm.c, COUNTIF(_xlpm.c, B2)>0)),Data!Q1:AD1,"ERR")} -> Rockets | D2: {=XLOOKUP(B2,Data!AG:AG,Data!AH:AH)} -> 6 | E2: Yes | F2: {=XLOOKUP(B2,Data!K:K,Data!K:K)} -> Rocket Launcher | G2: No | H2: Normal
A3: Copy | B3: {=TEXT(XLOOKUP(B2, Data!C:C, Data!B:B, 0), "00")} -> 19 | C3: {=TEXT(XLOOKUP(C2, Data!E:E, Data!B:B, 0), "00")} -> 05 | D3: {=TEXT(XLOOKUP(D2, Data!G:G, Data!B:B, 0), "00")} -> 06 | E3: {=TEXT(XLOOKUP(E2, Data!I:I, Data!B:B, 0), "00")} -> 01 | F3: {=TEXT(XLOOKUP(F2, Data!K:K, Data!J:J, 0), "00")} -> D3 | G3: {=TEXT(XLOOKUP(G2, Data!M:M, Data!B:B, 0), "00")} -> 00 | H3: {=TEXT(XLOOKUP(H2, Data!O:O, Data!B:B, 0), "00")} -> 01
A5: Advanced | B5: ZMG | C5: Grenades | D5: 34 | E5: Yes | F5: Juliett | G5: No | H5: Normal
A6: Copy | B6: {=TEXT(XLOOKUP(B5, Data!C:C, Data!B:B, 0), "00")} -> 09 | C6: {=TEXT(XLOOKUP(C5, Data!E:E, Data!B:B, 0), "00")} -> 04 | D6: {=TEXT(XLOOKUP(D5, Data!A:A, Data!B:B, 0), "00")} -> 22 | E6: {=TEXT(XLOOKUP(E5, Data!I:I, Data!B:B, 0), "00")} -> 01 | F6: {=TEXT(XLOOKUP(F5, Data!K:K, Data!B:B, 0), "00")} -> 00 | G6: {=TEXT(XLOOKUP(G5, Data!M:M, Data!B:B, 0), "00")} -> 00 | H6: {=TEXT(XLOOKUP(H5, Data!O:O, Data!B:B, 0), "00")} -> 01

Sheet Data
A1: INDEX | B1: 00 | C1: Weapon ID | D1: 01 | E1: Ammo Type | F1: 02 | G1: Ammo Count | H1: 03 | I1: Weapon Toggle | J1: 04 | K1: Prop ID | L1: 05 | M1: Unk | N1: 06 | O1: Scale | Q1: 9mm Ammo | R1: Rifle | S1: Cartridges | T1: Grenades | U1: Rockets | V1: Remote Mine | W1: Proximity Mine | X1: Timed Mine | Y1: Knife | Z1: Grenade Rounds | AA1: Magnum Bullets | AB1: Golden Bullets | AC1: Watch Laser | AD1: Tank | AE1: None | AG1: Unarmed | AH1: 0
A2: 00 | B2: 00 | C2: Nothing (No Pickup) | D2: 00 | E2: None | F2: 00 | G2: 0 | H2: 00 | I2: No | J2: =DEC2HEX(A98) -> 60 | K2: Nothing (No Pickup) | L2: 00 | M2: No | N2: 00 | O2: None | Q2: PP7 | R2: KF7 | S2: Shotgun | T2: Grenades | U2: Rocket Launcher | V2: Remote Mines | W2: Proximity Mines | X2: Timed Mines | Y2: Throwing Knife | Z2: Grenade Launcher | AA2: Couugar Magnum | AB2: Golden Gun | AC2: Watch Laser | AD2: Tank | AE2: Moonraker Laser | AG2: Hunting Knives | AH2: 1
A3: 01 | B3: 01 | C3: Unarmed | D3: 01 | E3: 9mm Ammo | F3: 01 | G3: 1 | H3: 01 | I3: Yes | J3: =DEC2HEX(A187) -> B9 | K3: Grenade Launcher | N3: 01 | O3: Normal | Q3: PP7 (Silenced) | R3: Phantom | S3: Automatic Shotgun | AE3: Detonator | AG3: Throwing Knives | AH3: 10
A4: 02 | B4: 02 | C4: Hunting Knives | D4: 03 | E4: Rifle Ammo | F4: 02 | G4: 2 | J4: =DEC2HEX(A188) -> BA | K4: Hunting Knife | N4: 02 | O4: Large | Q4: DD44 | R4: AR33 | AG4: PP7 | AH4: 50
A5: 03 | B5: 03 | C5: Throwing Knives | D5: 04 | E5: Cartridges | F5: 03 | G5: 3 | J5: =DEC2HEX(A189) -> BB | K5: Moonraker Laser | N5: 03 | O5: Huge | Q5: Klobb | R5: Sniper Rifle | AG5: PP7 (Silenced) | AH5: 50
A6: 04 | B6: 04 | C6: PP7 | D6: 05 | E6: Grenades | F6: 04 | G6: 4 | J6: =DEC2HEX(A190) -> BC | K6: AR33 | N6: 04 | O6: Why | Q6: ZMG | AG6: DD44 | AH6: 50
A7: 05 | B7: 05 | C7: PP7 (Silenced) | D7: 06 | E7: Rockets | F7: 05 | G7: 5 | J7: =DEC2HEX(A191) -> BD | K7: D5K | Q7: D5K | AG7: Klobb | AH7: 100
A8: 06 | B8: 06 | C8: DD44 | D8: 07 | E8: Remote Mine | F8: 06 | G8: 6 | J8: =DEC2HEX(A192) -> BE | K8: Cougar Magnum | Q8: D5K (Silenced) | AG8: KF7 | AH8: 100
A9: 07 | B9: 07 | C9: Klobb | D9: 08 | E9: Proximity Mine | F9: 07 | G9: 7 | J9: =DEC2HEX(A193) -> BF | K9: PP7 | Q9: RC-P90 | AG9: ZMG | AH9: 100
A10: 08 | B10: 08 | C10: KF7 | D10: 09 | E10: Timed Mine | F10: 08 | G10: 8 | J10: =DEC2HEX(A194) -> C0 | K10: Shotgun | Q10: Silver PP7 | AG10: D5K | AH10: 100
A11: 09 | B11: 09 | C11: ZMG | D11: 0A | E11: Knife | F11: 09 | G11: 9 | J11: =DEC2HEX(A195) -> C1 | K11: Klobb | Q11: Gold PP7 | AG11: D5K (Silenced) | AH11: 100
A12: 10 | B12: 0A | C12: D5K | D12: 0B | E12: Grenade Rounds | F12: 0A | G12: 10 | J12: =DEC2HEX(A196) -> C2 | K12: Phantom | AG12: Phantom | AH12: 100
A13: 11 | B13: 0B | C13: D5K (Silenced) | D13: 0C | E13: Magnum Bullets | F13: 0B | G13: 11 | J13: =DEC2HEX(A197) -> C3 | K13: ZMG | AG13: AR33 | AH13: 40
A14: 12 | B14: 0C | C14: Phantom | D14: 0D | E14: Golden Bullets | F14: 0C | G14: 12 | J14: =DEC2HEX(A198) -> C4 | K14: Grenade | AG14: PC-P90 | AH14: 100
A15: 13 | B15: 0D | C15: AR33 | D15: 18 | E15: Watch Laser | F15: 0D | G15: 13 | J15: =DEC2HEX(A199) -> C5 | K15: RC-P90 | AG15: Shotgun | AH15: 30
A16: 14 | B16: 0E | C16: PC-P90 | D16: C1 | E16: Tank | F16: 0E | G16: 14 | J16: =DEC2HEX(A201) -> C7 | K16: Remote Mine | AG16: Automatic Shotgun | AH16: 30
A17: 15 | B17: 0F | C17: Shotgun | F17: 0F | G17: 15 | J17: =DEC2HEX(A202) -> C8 | K17: Proximity Mine | AG17: Sniper Rifle | AH17: 50
A18: 16 | B18: 10 | C18: Automatic Shotgun | F18: 10 | G18: 16 | J18: =DEC2HEX(A203) -> C9 | K18: Timed Mine | AG18: Cougar Magnum | AH18: 50
A19: 17 | B19: 11 | C19: Sniper Rifle | F19: 11 | G19: 17 | J19: =DEC2HEX(A206) -> CC | K19: PP7 (Silenced) | AG19: Golden Gun | AH19: 10
A20: 18 | B20: 12 | C20: Cougar Magnum | F20: 12 | G20: 18 | J20: =DEC2HEX(A207) -> CD | K20: DD44 | AG20: Silver PP7 | AH20: 10
A21: 19 | B21: 13 | C21: Golden Gun | F21: 13 | G21: 19 | J21: =DEC2HEX(A208) -> CE | K21: D5K (Silenced) | AG21: Gold PP7 | AH21: 10
A22: 20 | B22: 14 | C22: Silver PP7 | F22: 14 | G22: 20 | J22: =DEC2HEX(A209) -> CF | K22: Automatic Shotgun | AG22: Moonraker Laser | AH22: 0
A23: 21 | B23: 15 | C23: Gold PP7 | F23: 15 | G23: 21 | J23: =DEC2HEX(A210) -> D0 | K23: Golden Gun | AG23: Watch Laser | AH23: 100
A24: 22 | B24: 16 | C24: Moonraker Laser | F24: 16 | G24: 22 | J24: =DEC2HEX(A211) -> D1 | K24: Throwing Knife | AG24: Grenade Launcher | AH24: 6
A25: 23 | B25: 17 | C25: Watch Laser | F25: 17 | G25: 23 | J25: =DEC2HEX(A212) -> D2 | K25: Sniper Rifle | AG25: Rocket Launcher | AH25: 6
A26: 24 | B26: 18 | C26: Grenade Launcher | F26: 18 | G26: 24 | J26: =DEC2HEX(A213) -> D3 | K26: Rocket Launcher | AG26: Grenades | AH26: 5
A27: 25 | B27: 19 | C27: Rocket Launcher | F27: 19 | G27: 25 | AG27: Timed Mines | AH27: 5
A28: 26 | B28: 1A | C28: Grenades | F28: 1A | G28: 26 | AG28: Proximity Mines | AH28: 5
A29: 27 | B29: 1B | C29: Timed Mines | F29: 1B | G29: 27 | AG29: Remote Mines | AH29: 5
A30: 28 | B30: 1C | C30: Proximity Mines | F30: 1C | G30: 28 | AG30: Detonator | AH30: 0
A31: 29 | B31: 1D | C31: Remote Mines | F31: 1D | G31: 29 | AG31: Tazer | AH31: 1
A32: 30 | B32: 1E | C32: Detonator | F32: 1E | G32: 30 | AG32: Tank | AH32: 5
A33: 31 | B33: 1F | C33: Tazer | F33: 1F | G33: 31
A34: 32 | B34: 20 | C34: Tank | F34: 20 | G34: 32
A35: 33 | B35: 21 | F35: 21 | G35: 33
A36: 34 | B36: 22 | F36: 22 | G36: 34
A37: 35 | B37: 23 | F37: 23 | G37: 35
A38: 36 | B38: 24 | F38: 24 | G38: 36
A39: 37 | B39: 25 | F39: 25 | G39: 37
A40: 38 | B40: 26 | F40: 26 | G40: 38
...
